2018-08-22 11:53:28,217 - root - ERROR - Exception: Connection error during token calculation: HTTPSConnectionPool(host='translate.google.com', port=443): Max retries exceeded with url: / (Caused by NewConnectionError('<urllib3.connection.VerifiedHTTPSConnection object at 0x7fc890106f10>: Failed to establish a new connection: [Errno -3] Temporary failure in name resolution',))
Traceback (most recent call last):
  File "/home/aws_cam/lambda_test/face-trigger-lambda/face-trigger-lambda/webcam_facerec.py", line 321, in infinite_infer_run
    speak(unknown=False, person_name=predicted_identity)
  File "/home/aws_cam/lambda_test/face-trigger-lambda/face-trigger-lambda/webcam_facerec.py", line 132, in speak
    tts.write_to_fp(sf)
  File "/home/aws_cam/lambda_test/local/lib/python2.7/site-packages/gtts/tts.py", line 192, in write_to_fp
    str(e))
gTTSError: Connection error during token calculation: HTTPSConnectionPool(host='translate.google.com', port=443): Max retries exceeded with url: / (Caused by NewConnectionError('<urllib3.connection.VerifiedHTTPSConnection object at 0x7fc890106f10>: Failed to establish a new connection: [Errno -3] Temporary failure in name resolution',))
2018-08-22 12:07:11,405 - root - ERROR - Exception: Connection error during token calculation: HTTPSConnectionPool(host='translate.google.com', port=443): Max retries exceeded with url: / (Caused by NewConnectionError('<urllib3.connection.VerifiedHTTPSConnection object at 0x7fc78e9caf10>: Failed to establish a new connection: [Errno -3] Temporary failure in name resolution',))
Traceback (most recent call last):
  File "/home/aws_cam/lambda_test/face-trigger-lambda/face-trigger-lambda/webcam_facerec.py", line 132, in speak
    tts.write_to_fp(sf)
  File "/home/aws_cam/lambda_test/local/lib/python2.7/site-packages/gtts/tts.py", line 192, in write_to_fp
    str(e))
gTTSError: Connection error during token calculation: HTTPSConnectionPool(host='translate.google.com', port=443): Max retries exceeded with url: / (Caused by NewConnectionError('<urllib3.connection.VerifiedHTTPSConnection object at 0x7fc78e9caf10>: Failed to establish a new connection: [Errno -3] Temporary failure in name resolution',))
2018-08-22 12:07:14,364 - root - ERROR - Exception: Connection error during token calculation: HTTPSConnectionPool(host='translate.google.com', port=443): Max retries exceeded with url: / (Caused by NewConnectionError('<urllib3.connection.VerifiedHTTPSConnection object at 0x7fc78e970d10>: Failed to establish a new connection: [Errno -3] Temporary failure in name resolution',))
Traceback (most recent call last):
  File "/home/aws_cam/lambda_test/face-trigger-lambda/face-trigger-lambda/webcam_facerec.py", line 132, in speak
    tts.write_to_fp(sf)
  File "/home/aws_cam/lambda_test/local/lib/python2.7/site-packages/gtts/tts.py", line 192, in write_to_fp
    str(e))
gTTSError: Connection error during token calculation: HTTPSConnectionPool(host='translate.google.com', port=443): Max retries exceeded with url: / (Caused by NewConnectionError('<urllib3.connection.VerifiedHTTPSConnection object at 0x7fc78e970d10>: Failed to establish a new connection: [Errno -3] Temporary failure in name resolution',))
2018-08-22 12:07:17,423 - root - ERROR - Exception: Connection error during token calculation: HTTPSConnectionPool(host='translate.google.com', port=443): Max retries exceeded with url: / (Caused by NewConnectionError('<urllib3.connection.VerifiedHTTPSConnection object at 0x7fc78e970c10>: Failed to establish a new connection: [Errno -3] Temporary failure in name resolution',))
Traceback (most recent call last):
  File "/home/aws_cam/lambda_test/face-trigger-lambda/face-trigger-lambda/webcam_facerec.py", line 132, in speak
    tts.write_to_fp(sf)
  File "/home/aws_cam/lambda_test/local/lib/python2.7/site-packages/gtts/tts.py", line 192, in write_to_fp
    str(e))
gTTSError: Connection error during token calculation: HTTPSConnectionPool(host='translate.google.com', port=443): Max retries exceeded with url: / (Caused by NewConnectionError('<urllib3.connection.VerifiedHTTPSConnection object at 0x7fc78e970c10>: Failed to establish a new connection: [Errno -3] Temporary failure in name resolution',))
2018-08-22 12:13:15,898 - root - ERROR - Exception: Connection error during token calculation: HTTPSConnectionPool(host='translate.google.com', port=443): Max retries exceeded with url: / (Caused by NewConnectionError('<urllib3.connection.VerifiedHTTPSConnection object at 0x7fa669dd2f10>: Failed to establish a new connection: [Errno -3] Temporary failure in name resolution',))
Traceback (most recent call last):
  File "/home/aws_cam/lambda_test/face-trigger-lambda/face-trigger-lambda/webcam_facerec.py", line 132, in speak
    tts.write_to_fp(sf)
  File "/home/aws_cam/lambda_test/local/lib/python2.7/site-packages/gtts/tts.py", line 192, in write_to_fp
    str(e))
gTTSError: Connection error during token calculation: HTTPSConnectionPool(host='translate.google.com', port=443): Max retries exceeded with url: / (Caused by NewConnectionError('<urllib3.connection.VerifiedHTTPSConnection object at 0x7fa669dd2f10>: Failed to establish a new connection: [Errno -3] Temporary failure in name resolution',))
2018-08-22 12:13:21,682 - root - ERROR - Exception: Connection error during token calculation: HTTPSConnectionPool(host='translate.google.com', port=443): Max retries exceeded with url: / (Caused by NewConnectionError('<urllib3.connection.VerifiedHTTPSConnection object at 0x7fa669d77d10>: Failed to establish a new connection: [Errno -3] Temporary failure in name resolution',))
Traceback (most recent call last):
  File "/home/aws_cam/lambda_test/face-trigger-lambda/face-trigger-lambda/webcam_facerec.py", line 132, in speak
    tts.write_to_fp(sf)
  File "/home/aws_cam/lambda_test/local/lib/python2.7/site-packages/gtts/tts.py", line 192, in write_to_fp
    str(e))
gTTSError: Connection error during token calculation: HTTPSConnectionPool(host='translate.google.com', port=443): Max retries exceeded with url: / (Caused by NewConnectionError('<urllib3.connection.VerifiedHTTPSConnection object at 0x7fa669d77d10>: Failed to establish a new connection: [Errno -3] Temporary failure in name resolution',))
2018-08-22 12:13:25,535 - root - ERROR - Exception: Connection error during token calculation: HTTPSConnectionPool(host='translate.google.com', port=443): Max retries exceeded with url: / (Caused by NewConnectionError('<urllib3.connection.VerifiedHTTPSConnection object at 0x7fa669d77c10>: Failed to establish a new connection: [Errno -3] Temporary failure in name resolution',))
Traceback (most recent call last):
  File "/home/aws_cam/lambda_test/face-trigger-lambda/face-trigger-lambda/webcam_facerec.py", line 132, in speak
    tts.write_to_fp(sf)
  File "/home/aws_cam/lambda_test/local/lib/python2.7/site-packages/gtts/tts.py", line 192, in write_to_fp
    str(e))
gTTSError: Connection error during token calculation: HTTPSConnectionPool(host='translate.google.com', port=443): Max retries exceeded with url: / (Caused by NewConnectionError('<urllib3.connection.VerifiedHTTPSConnection object at 0x7fa669d77c10>: Failed to establish a new connection: [Errno -3] Temporary failure in name resolution',))
2018-08-22 12:13:31,877 - root - ERROR - Exception: Connection error during token calculation: HTTPSConnectionPool(host='translate.google.com', port=443): Max retries exceeded with url: / (Caused by NewConnectionError('<urllib3.connection.VerifiedHTTPSConnection object at 0x7fa669d77c90>: Failed to establish a new connection: [Errno -3] Temporary failure in name resolution',))
Traceback (most recent call last):
  File "/home/aws_cam/lambda_test/face-trigger-lambda/face-trigger-lambda/webcam_facerec.py", line 132, in speak
    tts.write_to_fp(sf)
  File "/home/aws_cam/lambda_test/local/lib/python2.7/site-packages/gtts/tts.py", line 192, in write_to_fp
    str(e))
gTTSError: Connection error during token calculation: HTTPSConnectionPool(host='translate.google.com', port=443): Max retries exceeded with url: / (Caused by NewConnectionError('<urllib3.connection.VerifiedHTTPSConnection object at 0x7fa669d77c90>: Failed to establish a new connection: [Errno -3] Temporary failure in name resolution',))
2018-08-22 12:13:35,893 - root - ERROR - Exception: Connection error during token calculation: HTTPSConnectionPool(host='translate.google.com', port=443): Max retries exceeded with url: / (Caused by NewConnectionError('<urllib3.connection.VerifiedHTTPSConnection object at 0x7fa669d77d50>: Failed to establish a new connection: [Errno -3] Temporary failure in name resolution',))
Traceback (most recent call last):
  File "/home/aws_cam/lambda_test/face-trigger-lambda/face-trigger-lambda/webcam_facerec.py", line 132, in speak
    tts.write_to_fp(sf)
  File "/home/aws_cam/lambda_test/local/lib/python2.7/site-packages/gtts/tts.py", line 192, in write_to_fp
    str(e))
gTTSError: Connection error during token calculation: HTTPSConnectionPool(host='translate.google.com', port=443): Max retries exceeded with url: / (Caused by NewConnectionError('<urllib3.connection.VerifiedHTTPSConnection object at 0x7fa669d77d50>: Failed to establish a new connection: [Errno -3] Temporary failure in name resolution',))
2018-08-22 12:13:39,203 - root - ERROR - Exception: Connection error during token calculation: HTTPSConnectionPool(host='translate.google.com', port=443): Max retries exceeded with url: / (Caused by NewConnectionError('<urllib3.connection.VerifiedHTTPSConnection object at 0x7fa669d77c50>: Failed to establish a new connection: [Errno -3] Temporary failure in name resolution',))
Traceback (most recent call last):
  File "/home/aws_cam/lambda_test/face-trigger-lambda/face-trigger-lambda/webcam_facerec.py", line 132, in speak
    tts.write_to_fp(sf)
  File "/home/aws_cam/lambda_test/local/lib/python2.7/site-packages/gtts/tts.py", line 192, in write_to_fp
    str(e))
gTTSError: Connection error during token calculation: HTTPSConnectionPool(host='translate.google.com', port=443): Max retries exceeded with url: / (Caused by NewConnectionError('<urllib3.connection.VerifiedHTTPSConnection object at 0x7fa669d77c50>: Failed to establish a new connection: [Errno -3] Temporary failure in name resolution',))
2018-08-22 12:13:42,242 - root - ERROR - Exception: Connection error during token calculation: HTTPSConnectionPool(host='translate.google.com', port=443): Max retries exceeded with url: / (Caused by NewConnectionError('<urllib3.connection.VerifiedHTTPSConnection object at 0x7fa669d77b50>: Failed to establish a new connection: [Errno -3] Temporary failure in name resolution',))
Traceback (most recent call last):
  File "/home/aws_cam/lambda_test/face-trigger-lambda/face-trigger-lambda/webcam_facerec.py", line 132, in speak
    tts.write_to_fp(sf)
  File "/home/aws_cam/lambda_test/local/lib/python2.7/site-packages/gtts/tts.py", line 192, in write_to_fp
    str(e))
gTTSError: Connection error during token calculation: HTTPSConnectionPool(host='translate.google.com', port=443): Max retries exceeded with url: / (Caused by NewConnectionError('<urllib3.connection.VerifiedHTTPSConnection object at 0x7fa669d77b50>: Failed to establish a new connection: [Errno -3] Temporary failure in name resolution',))
2018-08-22 12:13:47,572 - root - ERROR - Exception: Connection error during token calculation: HTTPSConnectionPool(host='translate.google.com', port=443): Max retries exceeded with url: / (Caused by NewConnectionError('<urllib3.connection.VerifiedHTTPSConnection object at 0x7fa669d77b90>: Failed to establish a new connection: [Errno -3] Temporary failure in name resolution',))
Traceback (most recent call last):
  File "/home/aws_cam/lambda_test/face-trigger-lambda/face-trigger-lambda/webcam_facerec.py", line 132, in speak
    tts.write_to_fp(sf)
  File "/home/aws_cam/lambda_test/local/lib/python2.7/site-packages/gtts/tts.py", line 192, in write_to_fp
    str(e))
gTTSError: Connection error during token calculation: HTTPSConnectionPool(host='translate.google.com', port=443): Max retries exceeded with url: / (Caused by NewConnectionError('<urllib3.connection.VerifiedHTTPSConnection object at 0x7fa669d77b90>: Failed to establish a new connection: [Errno -3] Temporary failure in name resolution',))
2018-08-22 12:13:53,797 - root - ERROR - Exception: Connection error during token calculation: HTTPSConnectionPool(host='translate.google.com', port=443): Max retries exceeded with url: / (Caused by NewConnectionError('<urllib3.connection.VerifiedHTTPSConnection object at 0x7fa669d77bd0>: Failed to establish a new connection: [Errno -3] Temporary failure in name resolution',))
Traceback (most recent call last):
  File "/home/aws_cam/lambda_test/face-trigger-lambda/face-trigger-lambda/webcam_facerec.py", line 132, in speak
    tts.write_to_fp(sf)
  File "/home/aws_cam/lambda_test/local/lib/python2.7/site-packages/gtts/tts.py", line 192, in write_to_fp
    str(e))
gTTSError: Connection error during token calculation: HTTPSConnectionPool(host='translate.google.com', port=443): Max retries exceeded with url: / (Caused by NewConnectionError('<urllib3.connection.VerifiedHTTPSConnection object at 0x7fa669d77bd0>: Failed to establish a new connection: [Errno -3] Temporary failure in name resolution',))
2018-08-22 12:14:08,608 - root - ERROR - Exception: Connection error during token calculation: HTTPSConnectionPool(host='translate.google.com', port=443): Max retries exceeded with url: / (Caused by NewConnectionError('<urllib3.connection.VerifiedHTTPSConnection object at 0x7fa669d77ad0>: Failed to establish a new connection: [Errno -3] Temporary failure in name resolution',))
Traceback (most recent call last):
  File "/home/aws_cam/lambda_test/face-trigger-lambda/face-trigger-lambda/webcam_facerec.py", line 132, in speak
    tts.write_to_fp(sf)
  File "/home/aws_cam/lambda_test/local/lib/python2.7/site-packages/gtts/tts.py", line 192, in write_to_fp
    str(e))
gTTSError: Connection error during token calculation: HTTPSConnectionPool(host='translate.google.com', port=443): Max retries exceeded with url: / (Caused by NewConnectionError('<urllib3.connection.VerifiedHTTPSConnection object at 0x7fa669d77ad0>: Failed to establish a new connection: [Errno -3] Temporary failure in name resolution',))
2018-08-22 12:14:11,609 - root - ERROR - Exception: Connection error during token calculation: HTTPSConnectionPool(host='translate.google.com', port=443): Max retries exceeded with url: / (Caused by NewConnectionError('<urllib3.connection.VerifiedHTTPSConnection object at 0x7fa669d77910>: Failed to establish a new connection: [Errno -3] Temporary failure in name resolution',))
Traceback (most recent call last):
  File "/home/aws_cam/lambda_test/face-trigger-lambda/face-trigger-lambda/webcam_facerec.py", line 132, in speak
    tts.write_to_fp(sf)
  File "/home/aws_cam/lambda_test/local/lib/python2.7/site-packages/gtts/tts.py", line 192, in write_to_fp
    str(e))
gTTSError: Connection error during token calculation: HTTPSConnectionPool(host='translate.google.com', port=443): Max retries exceeded with url: / (Caused by NewConnectionError('<urllib3.connection.VerifiedHTTPSConnection object at 0x7fa669d77910>: Failed to establish a new connection: [Errno -3] Temporary failure in name resolution',))
2018-08-22 12:40:40,526 - root - ERROR - Exception: global name 'unknown_person_msg' is not defined
Traceback (most recent call last):
  File "/home/aws_cam/lambda_test/face-trigger-lambda/face-trigger-lambda/webcam_facerec.py", line 121, in speak
    msg = unknown_person_msg
NameError: global name 'unknown_person_msg' is not defined
2018-08-22 12:40:59,694 - root - ERROR - Exception: global name 'unknown_person_msg' is not defined
Traceback (most recent call last):
  File "/home/aws_cam/lambda_test/face-trigger-lambda/face-trigger-lambda/webcam_facerec.py", line 121, in speak
    msg = unknown_person_msg
NameError: global name 'unknown_person_msg' is not defined
2018-08-22 12:41:24,704 - root - ERROR - Exception: global name 'unknown_person_msg' is not defined
Traceback (most recent call last):
  File "/home/aws_cam/lambda_test/face-trigger-lambda/face-trigger-lambda/webcam_facerec.py", line 121, in speak
    msg = unknown_person_msg
NameError: global name 'unknown_person_msg' is not defined
